<?xml version="1.0" encoding="utf-8"?>
<!-- =================================================================================== -->
<!-- |    This document was autogenerated by xacro from /home/phiggin1/catkin_ws/src/umbc_husky/urdf/umbc_husky.urdf.xacro | -->
<!-- |    EDITING THIS FILE BY HAND IS NOT RECOMMENDED                                 | -->
<!-- =================================================================================== -->
<!--
Software License Agreement (BSD)

\file      husky.urdf.xacro
\authors   Paul Bovbel <pbovbel@clearpathrobotics.com>, Devon Ash <dash@clearpathrobotics.com>
\copyright Copyright (c) 2015, Clearpath Robotics, Inc., All rights reserved.

Redistribution and use in source and binary forms, with or without modification, are permitted provided that
the following conditions are met:
 * Redistributions of source code must retain the above copyright notice, this list of conditions and the
   following disclaimer.
 * Redistributions in binary form must reproduce the above copyright notice, this list of conditions and the
   following disclaimer in the documentation and/or other materials provided with the distribution.
 * Neither the name of Clearpath Robotics nor the names of its contributors may be used to endorse or promote
   products derived from this software without specific prior written permission.

THIS SOFTWARE IS PROVIDED BY THE COPYRIGHT HOLDERS AND CONTRIBUTORS "AS IS" AND ANY EXPRESS OR IMPLIED WAR-
RANTIES, INCLUDING, BUT NOT LIMITED TO, THE IMPLIED WARRANTIES OF MERCHANTABILITY AND FITNESS FOR A PARTICULAR
PURPOSE ARE DISCLAIMED. IN NO EVENT SHALL THE COPYRIGHT HOLDER OR CONTRIBUTORS BE LIABLE FOR ANY DIRECT, IN-
DIRECT, INCIDENTAL, SPECIAL, EXEMPLARY, OR CONSEQUENTIAL DAMAGES (INCLUDING, BUT NOT LIMITED TO, PROCUREMENT
OF SUBSTITUTE GOODS OR SERVICES; LOSS OF USE, DATA, OR PROFITS; OR BUSINESS INTERRUPTION) HOWEVER CAUSED AND
ON ANY THEORY OF LIABILITY, WHETHER IN CONTRACT, STRICT LIABILITY, OR TORT (INCLUDING NEGLIGENCE OR OTHERWISE)
ARISING IN ANY WAY OUT OF THE USE OF THIS SOFTWARE, EVEN IF ADVISED OF THE POSSIBILITY OF SUCH DAMAGE.
-->
<robot name="husky">
  <!-- Base link is the center of the robot's bottom plate -->
  <link name="base_link">
    <visual>
      <origin rpy="0 0 0" xyz="0 0 0"/>
      <geometry>
        <mesh filename="package://husky_description/meshes/base_link.dae"/>
      </geometry>
    </visual>
    <collision>
      <origin rpy="0 0 0" xyz="0.0 0 0.061875"/>
      <geometry>
        <box size="0.9874 0.5709 0.12375"/>
      </geometry>
    </collision>
    <collision>
      <origin rpy="0 0 0" xyz="0 0 0.175625"/>
      <geometry>
        <box size="0.78992 0.5709 0.10375"/>
      </geometry>
    </collision>
  </link>
  <!-- Base footprint is on the ground under the robot -->
  <link name="base_footprint"/>
  <joint name="base_footprint_joint" type="fixed">
    <origin rpy="0 0 0" xyz="0 0 -0.13228"/>
    <parent link="base_link"/>
    <child link="base_footprint"/>
  </joint>
  <!-- Interial link stores the robot's inertial information -->
  <link name="inertial_link">
    <inertial>
      <mass value="46.034"/>
      <origin xyz="-0.00065 -0.085 0.062"/>
      <inertia ixx="0.6022" ixy="-0.02364" ixz="-0.1197" iyy="1.7386" iyz="-0.001544" izz="2.0296"/>
    </inertial>
  </link>
  <joint name="inertial_joint" type="fixed">
    <origin rpy="0 0 0" xyz="0 0 0"/>
    <parent link="base_link"/>
    <child link="inertial_link"/>
  </joint>
  <!-- IMU Link is the standard mounting position for the UM6 IMU.-->
  <!-- Can be modified with environment variables in /etc/ros/setup.bash -->
  <link name="imu_link"/>
  <joint name="imu_joint" type="fixed">
    <origin rpy="0 -1.5708 3.1416" xyz="0.19 0 0.149"/>
    <parent link="base_link"/>
    <child link="imu_link"/>
  </joint>
  <gazebo reference="imu_link">
  </gazebo>
  <link name="front_left_wheel_link">
    <inertial>
      <mass value="2.637"/>
      <origin xyz="0 0 0"/>
      <inertia ixx="0.02467" ixy="0" ixz="0" iyy="0.04411" iyz="0" izz="0.02467"/>
    </inertial>
    <visual>
      <origin rpy="0 0 0" xyz="0 0 0"/>
      <geometry>
        <mesh filename="package://husky_description/meshes/wheel.dae"/>
      </geometry>
    </visual>
    <collision>
      <origin rpy="1.570795 0 0" xyz="0 0 0"/>
      <geometry>
        <cylinder length="0.1143" radius="0.1651"/>
      </geometry>
    </collision>
  </link>
  <gazebo reference="front_left_wheel_link">
    <mu1 value="1.0"/>
    <mu2 value="1.0"/>
    <kp value="10000000.0"/>
    <kd value="1.0"/>
    <fdir1 value="1 0 0"/>
  </gazebo>
  <joint name="front_left_wheel" type="continuous">
    <parent link="base_link"/>
    <child link="front_left_wheel_link"/>
    <origin rpy="0 0 0" xyz="0.256 0.2854 0.03282"/>
    <axis rpy="0 0 0" xyz="0 1 0"/>
  </joint>
  <transmission name="front_left_wheel_trans" type="SimpleTransmission">
    <type>transmission_interface/SimpleTransmission</type>
    <actuator name="front_left_wheel_motor">
      <mechanicalReduction>1</mechanicalReduction>
    </actuator>
    <joint name="front_left_wheel">
      <hardwareInterface>hardware_interface/VelocityJointInterface</hardwareInterface>
    </joint>
  </transmission>
  <link name="front_right_wheel_link">
    <inertial>
      <mass value="2.637"/>
      <origin xyz="0 0 0"/>
      <inertia ixx="0.02467" ixy="0" ixz="0" iyy="0.04411" iyz="0" izz="0.02467"/>
    </inertial>
    <visual>
      <origin rpy="0 0 0" xyz="0 0 0"/>
      <geometry>
        <mesh filename="package://husky_description/meshes/wheel.dae"/>
      </geometry>
    </visual>
    <collision>
      <origin rpy="1.570795 0 0" xyz="0 0 0"/>
      <geometry>
        <cylinder length="0.1143" radius="0.1651"/>
      </geometry>
    </collision>
  </link>
  <gazebo reference="front_right_wheel_link">
    <mu1 value="1.0"/>
    <mu2 value="1.0"/>
    <kp value="10000000.0"/>
    <kd value="1.0"/>
    <fdir1 value="1 0 0"/>
  </gazebo>
  <joint name="front_right_wheel" type="continuous">
    <parent link="base_link"/>
    <child link="front_right_wheel_link"/>
    <origin rpy="0 0 0" xyz="0.256 -0.2854 0.03282"/>
    <axis rpy="0 0 0" xyz="0 1 0"/>
  </joint>
  <transmission name="front_right_wheel_trans" type="SimpleTransmission">
    <type>transmission_interface/SimpleTransmission</type>
    <actuator name="front_right_wheel_motor">
      <mechanicalReduction>1</mechanicalReduction>
    </actuator>
    <joint name="front_right_wheel">
      <hardwareInterface>hardware_interface/VelocityJointInterface</hardwareInterface>
    </joint>
  </transmission>
  <link name="rear_left_wheel_link">
    <inertial>
      <mass value="2.637"/>
      <origin xyz="0 0 0"/>
      <inertia ixx="0.02467" ixy="0" ixz="0" iyy="0.04411" iyz="0" izz="0.02467"/>
    </inertial>
    <visual>
      <origin rpy="0 0 0" xyz="0 0 0"/>
      <geometry>
        <mesh filename="package://husky_description/meshes/wheel.dae"/>
      </geometry>
    </visual>
    <collision>
      <origin rpy="1.570795 0 0" xyz="0 0 0"/>
      <geometry>
        <cylinder length="0.1143" radius="0.1651"/>
      </geometry>
    </collision>
  </link>
  <gazebo reference="rear_left_wheel_link">
    <mu1 value="1.0"/>
    <mu2 value="1.0"/>
    <kp value="10000000.0"/>
    <kd value="1.0"/>
    <fdir1 value="1 0 0"/>
  </gazebo>
  <joint name="rear_left_wheel" type="continuous">
    <parent link="base_link"/>
    <child link="rear_left_wheel_link"/>
    <origin rpy="0 0 0" xyz="-0.256 0.2854 0.03282"/>
    <axis rpy="0 0 0" xyz="0 1 0"/>
  </joint>
  <transmission name="rear_left_wheel_trans" type="SimpleTransmission">
    <type>transmission_interface/SimpleTransmission</type>
    <actuator name="rear_left_wheel_motor">
      <mechanicalReduction>1</mechanicalReduction>
    </actuator>
    <joint name="rear_left_wheel">
      <hardwareInterface>hardware_interface/VelocityJointInterface</hardwareInterface>
    </joint>
  </transmission>
  <link name="rear_right_wheel_link">
    <inertial>
      <mass value="2.637"/>
      <origin xyz="0 0 0"/>
      <inertia ixx="0.02467" ixy="0" ixz="0" iyy="0.04411" iyz="0" izz="0.02467"/>
    </inertial>
    <visual>
      <origin rpy="0 0 0" xyz="0 0 0"/>
      <geometry>
        <mesh filename="package://husky_description/meshes/wheel.dae"/>
      </geometry>
    </visual>
    <collision>
      <origin rpy="1.570795 0 0" xyz="0 0 0"/>
      <geometry>
        <cylinder length="0.1143" radius="0.1651"/>
      </geometry>
    </collision>
  </link>
  <gazebo reference="rear_right_wheel_link">
    <mu1 value="1.0"/>
    <mu2 value="1.0"/>
    <kp value="10000000.0"/>
    <kd value="1.0"/>
    <fdir1 value="1 0 0"/>
  </gazebo>
  <joint name="rear_right_wheel" type="continuous">
    <parent link="base_link"/>
    <child link="rear_right_wheel_link"/>
    <origin rpy="0 0 0" xyz="-0.256 -0.2854 0.03282"/>
    <axis rpy="0 0 0" xyz="0 1 0"/>
  </joint>
  <transmission name="rear_right_wheel_trans" type="SimpleTransmission">
    <type>transmission_interface/SimpleTransmission</type>
    <actuator name="rear_right_wheel_motor">
      <mechanicalReduction>1</mechanicalReduction>
    </actuator>
    <joint name="rear_right_wheel">
      <hardwareInterface>hardware_interface/VelocityJointInterface</hardwareInterface>
    </joint>
  </transmission>
  <!-- Spawn Husky chassis -->
  <link name="top_chassis_link">
    <visual>
      <origin rpy="0 0 0" xyz="0 0 0"/>
      <geometry>
        <mesh filename="package://husky_description/meshes/top_chassis.dae"/>
      </geometry>
    </visual>
  </link>
  <!-- Attach chassis to the robot -->
  <joint name="top_chassis_joint" type="fixed">
    <parent link="base_link"/>
    <child link="top_chassis_link"/>
  </joint>
  <!-- Spawn user rails -->
  <link name="user_rail_link">
    <visual>
      <geometry>
        <mesh filename="package://husky_description/meshes/user_rail.dae"/>
      </geometry>
    </visual>
  </link>
  <!-- Attach user rails to base link -->
  <joint name="user_rail" type="fixed">
    <origin rpy="0 0 0" xyz="0.272 0 0.245"/>
    <parent link="base_link"/>
    <child link="user_rail_link"/>
  </joint>
  <!-- Spawn front bumper link -->
  <link name="front_bumper_link">
    <visual>
      <geometry>
        <mesh filename="package://husky_description/meshes/bumper.dae"/>
      </geometry>
    </visual>
  </link>
  <!-- Attach front bumper -->
  <joint name="front_bumper" type="fixed">
    <origin rpy="0 0 0" xyz="0.48 0 0.091"/>
    <parent link="base_link"/>
    <child link="front_bumper_link"/>
  </joint>
  <!-- Spawn rear bumper link -->
  <link name="rear_bumper_link">
    <visual>
      <geometry>
        <mesh filename="package://husky_description/meshes/bumper.dae"/>
      </geometry>
    </visual>
  </link>
  <!-- Attach rear bumper -->
  <joint name="rear_bumper" type="fixed">
    <origin rpy="0 0 3.14159" xyz="-0.48 0 0.091"/>
    <parent link="base_link"/>
    <child link="rear_bumper_link"/>
  </joint>
  <link name="top_plate_link">
    <visual>
      <origin rpy="0 0 0" xyz="0 0 0"/>
      <geometry>
        <mesh filename="package://husky_description/meshes/top_plate.dae"/>
      </geometry>
    </visual>
    <collision>
      <origin rpy="0 0 0" xyz="0 0 0"/>
      <geometry>
        <mesh filename="package://husky_description/meshes/top_plate.stl"/>
      </geometry>
    </collision>
  </link>
  <!-- Attach top plate -->
  <joint name="top_plate_joint" type="fixed">
    <parent link="base_link"/>
    <child link="top_plate_link"/>
    <origin rpy="0 0 0" xyz="0.0812 0 0.245"/>
  </joint>
  <!-- Top plate front link -->
  <joint name="top_plate_front_joint" type="fixed">
    <parent link="top_plate_link"/>
    <child link="top_plate_front_link"/>
    <origin rpy="0 0 0" xyz="0.36367 0 0.00639"/>
  </joint>
  <!-- Top plate rear link-->
  <joint name="top_plate_rear_joint" type="fixed">
    <parent link="top_plate_link"/>
    <child link="top_plate_rear_link"/>
    <origin rpy="0 0 0" xyz="-0.36633 0 0.00639"/>
  </joint>
  <link name="top_plate_front_link"/>
  <link name="top_plate_rear_link"/>
  <!-- Spawn the sensor arch link -->
  <link name="sensor_arch_mount_link">
    <origin rpy="0 0 0" xyz="0 0 0"/>
    <visual>
      <geometry>
        <mesh filename="package://husky_description/meshes/accessories/510_mm_sensor_arch.dae"/>
      </geometry>
    </visual>
    <collision>
      <origin rpy="0 0 0" xyz="0 0 0"/>
      <geometry>
        <mesh filename="package://husky_description/meshes/accessories/510_mm_sensor_arch.dae"/>
      </geometry>
    </collision>
  </link>
  <!-- Attach the sensor arch to the top plate -->
  <joint name="sensor_arch_mount" type="fixed">
    <origin rpy="0 0 -3.14" xyz="-0.35 0 0.51"/>
    <parent link="top_plate_link"/>
    <child link="sensor_arch_mount_link"/>
  </joint>
  <joint name="kinect_frame_joint" type="fixed">
    <origin rpy="0 0.18 3.14" xyz="0 0 0"/>
    <parent link="sensor_arch_mount_link"/>
    <child link="camera_link"/>
  </joint>
  <!-- Create kinect reference frame -->
  <!-- Add mesh for kinect -->
  <link name="camera_link">
    <origin rpy="0 0 0" xyz="0 0 0"/>

  </link>
  <joint name="camera_optical_joint" type="fixed">
    <origin rpy="-1.5708 0 -1.5708" xyz="0 0 0"/>
    <parent link="camera_link"/>
    <child link="camera_frame_optical"/>
  </joint>
  <link name="camera_frame_optical"/>
  <gazebo>
    <plugin filename="libgazebo_ros_control.so" name="gazebo_ros_control">
    </plugin>
  </gazebo>
  <gazebo>
    <plugin filename="libhector_gazebo_ros_imu.so" name="imu_controller">
      <robotNamespace>/</robotNamespace>
      <updateRate>50.0</updateRate>
      <bodyName>base_link</bodyName>
      <topicName>imu/data</topicName>
      <accelDrift>0.005 0.005 0.005</accelDrift>
      <accelGaussianNoise>0.005 0.005 0.005</accelGaussianNoise>
      <rateDrift>0.005 0.005 0.005 </rateDrift>
      <rateGaussianNoise>0.005 0.005 0.005 </rateGaussianNoise>
      <headingDrift>0.005</headingDrift>
      <headingGaussianNoise>0.005</headingGaussianNoise>
    </plugin>
  </gazebo>
  <gazebo>
    <plugin filename="libhector_gazebo_ros_gps.so" name="gps_controller">
      <robotNamespace>/</robotNamespace>
      <updateRate>40</updateRate>
      <bodyName>base_link</bodyName>
      <frameId>base_link</frameId>
      <topicName>navsat/fix</topicName>
      <velocityTopicName>navsat/vel</velocityTopicName>
      <referenceLatitude>49.9</referenceLatitude>
      <referenceLongitude>8.9</referenceLongitude>
      <referenceHeading>0</referenceHeading>
      <referenceAltitude>0</referenceAltitude>
      <drift>0.0001 0.0001 0.0001</drift>
    </plugin>
  </gazebo>
  <!-- Optional custom includes. -->
  <link name="umbc_structure_mesh">
    <visual>
      <geometry>
        <mesh filename="package://umbc_husky/meshes/UMBC_structure.STL"/>
      </geometry>
      <material name="charcoal">
        <color rgba="0.2 0.2 0.2 1"/>
      </material>
    </visual>
  </link>
  <joint name="top_plate_to_umbc_tower_mesh" type="fixed">
    <parent link="top_plate_link"/>
    <child link="umbc_structure_mesh"/>
    <origin rpy="0 0 0" xyz="-0.06 0 0.007"/>
  </joint>
  <link name="upper_top_plate">
    <visual>
      <geometry>
        <mesh filename="package://husky_description/meshes/top_plate.dae"/>
      </geometry>
    </visual>
    <collision>
      <geometry>
        <mesh filename="package://husky_description/meshes/top_plate.dae"/>
      </geometry>
    </collision>
  </link>
  <joint name="top_plate_to_upper_top_plate" type="fixed">
    <parent link="top_plate_link"/>
    <child link="upper_top_plate"/>
    <origin rpy="0 0 0" xyz="0.0 0.0 0.307"/>
  </joint>
  <!-- Create a fixed joint to connect the Kinect2 to the rest of the robot -->
  <link name="kinect2_link"/>
  <joint name="top_plate_to_kinect2" type="fixed">
    <parent link="top_plate_link"/>
    <child link="kinect2_link"/>
    <origin rpy="-1.57079633 0 -1.57079633" xyz="-0.30 -0.1 0.57"/> 
  </joint>
  <!-- links      		mesh_no
   base           		0
   shoulder       		1
   arm            		2
   forearm        		3
   wrist          		4
   arm_mico       		5
   arm_half1 (7dof)		6
   arm_half2 (7dof)		7
   wrist_spherical_1  8
   wrist_spherical_2  9

   hand 3 finger  		55
   hand_2finger   		56
   finger_proximal		57
   finger_distal      58
-->
  <!-- links      		mesh_no
   base           		0
   shoulder       		1
   arm            		2
   forearm        		3
   wrist          		4
   arm_mico       		5
   arm_half1 (7dof)		6
   arm_half2 (7dof)		7
   wrist_spherical_1  8
   wrist_spherical_2  9

   hand 3 finger  		55
   hand_2finger   		56
   finger_proximal		57
   finger_distal      58
-->
  <link name="right_arm_link"/>
  <joint name="top_plate_to_right_arm" type="fixed">
    <parent link="top_plate_link"/>
    <child link="right_arm_link"/>
    <!-- org <origin xyz="0.21 -0.197 0.315" rpy="0 0 1.57079633" /> -->
    <origin rpy="0 0 0" xyz="0.22 -0.197 0.315"/>
  </joint>
  <!-- ros_control plugin -->
  <!-- <gazebo>
    <plugin filename="libgazebo_ros_control.so" name="gazebo_ros_control">
      <robotNamespace>j2n6s300</robotNamespace>
      <robotSimType>gazebo_ros_control/DefaultRobotHWSim</robotSimType>
      <legacyModeNS>true</legacyModeNS>
    </plugin>
  </gazebo> -->
  <link name="j2n6s300_link_base">
    <visual>
      <geometry>
        <mesh filename="package://kinova_description/meshes/base.dae"/>
      </geometry>
      <material name="carbon_fiber">
        <color rgba="0.792156862745098 0.819607843137255 0.933333333333333 1"/>
      </material>
    </visual>
    <collision>
      <geometry>
        <mesh filename="package://kinova_description/meshes/base.dae"/>
      </geometry>
    </collision>
    <inertial>
      <mass value="0.46784"/>
      <origin rpy="0 0 0" xyz="0 0 0.1255"/>
      <inertia ixx="0.000951270861568" ixy="0" ixz="0" iyy="0.000951270861568" iyz="0" izz="0.000374272"/>
    </inertial>
  </link>
  <joint name="j2n6s300_joint_base" type="fixed">
    <parent link="right_arm_link"/>
    <child link="j2n6s300_link_base"/>
    <axis xyz="0 0 0"/>
    <limit effort="0" lower="0" upper="0" velocity="0"/>
    <origin rpy="0 0 0" xyz="0 0 0"/>
    <dynamics damping="0.0" friction="0.0"/>
  </joint>
  <link name="j2n6s300_link_1">
    <visual>
      <geometry>
        <mesh filename="package://kinova_description/meshes/shoulder.dae"/>
      </geometry>
      <material name="carbon_fiber">
        <color rgba="0.792156862745098 0.819607843137255 0.933333333333333 1"/>
      </material>
    </visual>
    <collision>
      <geometry>
        <mesh filename="package://kinova_description/meshes/shoulder.dae"/>
      </geometry>
    </collision>
    <visual>
      <geometry>
        <mesh filename="package://kinova_description/meshes/ring_big.dae"/>
      </geometry>
    </visual>
    <collision>
      <geometry>
        <mesh filename="package://kinova_description/meshes/ring_big.dae"/>
      </geometry>
    </collision>
    <inertial>
      <mass value="0.7477"/>
      <origin xyz="0 -0.002 -0.0605"/>
      <inertia ixx="0.00152031725204" ixy="0" ixz="0" iyy="0.00152031725204" iyz="0" izz="0.00059816"/>
    </inertial>
  </link>
  <joint name="j2n6s300_joint_1" type="continuous">
    <parent link="j2n6s300_link_base"/>
    <child link="j2n6s300_link_1"/>
    <axis xyz="0 0 1"/>
    <limit effort="40" lower="-6.28318530718" upper="6.28318530718" velocity="0.628318530718"/>
    <origin rpy="0 3.14159265359 0" xyz="0 0 0.15675"/>
    <dynamics damping="0.0" friction="0.0"/>
  </joint>
  <transmission name="j2n6s300_joint_1_trans">
    <type>transmission_interface/SimpleTransmission</type>
    <joint name="j2n6s300_joint_1">
      <hardwareInterface>hardware_interface/EffortJointInterface</hardwareInterface>
    </joint>
    <actuator name="j2n6s300_joint_1_actuator">
      <hardwareInterface>hardware_interface/EffortJointInterface</hardwareInterface>
      <mechanicalReduction>160</mechanicalReduction>
    </actuator>
  </transmission>
  <!--For torque sensing in simulation-->
  <gazebo reference="j2n6s300_joint_1">
    <provideFeedback>true</provideFeedback>
  </gazebo>
  <gazebo>
    <plugin filename="libgazebo_ros_ft_sensor.so" name="ft_sensor">
      <updateRate>30.0</updateRate>
      <topicName>j2n6s300_joint_1_ft_sensor_topic</topicName>
      <jointName>j2n6s300_joint_1</jointName>
    </plugin>
  </gazebo>
  <link name="j2n6s300_link_2">
    <visual>
      <geometry>
        <mesh filename="package://kinova_description/meshes/arm.dae"/>
      </geometry>
      <material name="carbon_fiber">
        <color rgba="0.792156862745098 0.819607843137255 0.933333333333333 1"/>
      </material>
    </visual>
    <collision>
      <geometry>
        <mesh filename="package://kinova_description/meshes/arm.dae"/>
      </geometry>
    </collision>
    <visual>
      <geometry>
        <mesh filename="package://kinova_description/meshes/ring_big.dae"/>
      </geometry>
    </visual>
    <collision>
      <geometry>
        <mesh filename="package://kinova_description/meshes/ring_big.dae"/>
      </geometry>
    </collision>
    <inertial>
      <mass value="0.99"/>
      <origin xyz="0 -0.2065 -0.01"/>
      <inertia ixx="0.010502207991" ixy="0" ixz="0" iyy="0.000792" iyz="0" izz="0.010502207991"/>
    </inertial>
  </link>
  <joint name="j2n6s300_joint_2" type="revolute">
    <parent link="j2n6s300_link_1"/>
    <child link="j2n6s300_link_2"/>
    <axis xyz="0 0 1"/>
    <limit effort="80" lower="0.820304748437" upper="5.46288055874" velocity="0.628318530718"/>
    <origin rpy="-1.57079632679 0 3.14159265359" xyz="0 0.0016 -0.11875"/>
    <dynamics damping="0.0" friction="0.0"/>
  </joint>
  <transmission name="j2n6s300_joint_2_trans">
    <type>transmission_interface/SimpleTransmission</type>
    <joint name="j2n6s300_joint_2">
      <hardwareInterface>hardware_interface/EffortJointInterface</hardwareInterface>
    </joint>
    <actuator name="j2n6s300_joint_2_actuator">
      <hardwareInterface>hardware_interface/EffortJointInterface</hardwareInterface>
      <mechanicalReduction>160</mechanicalReduction>
    </actuator>
  </transmission>
  <!--For torque sensing in simulation-->
  <gazebo reference="j2n6s300_joint_2">
    <provideFeedback>true</provideFeedback>
  </gazebo>
  <gazebo>
    <plugin filename="libgazebo_ros_ft_sensor.so" name="ft_sensor">
      <updateRate>30.0</updateRate>
      <topicName>j2n6s300_joint_2_ft_sensor_topic</topicName>
      <jointName>j2n6s300_joint_2</jointName>
    </plugin>
  </gazebo>
  <link name="j2n6s300_link_3">
    <visual>
      <geometry>
        <mesh filename="package://kinova_description/meshes/forearm.dae"/>
      </geometry>
      <material name="carbon_fiber">
        <color rgba="0.792156862745098 0.819607843137255 0.933333333333333 1"/>
      </material>
    </visual>
    <collision>
      <geometry>
        <mesh filename="package://kinova_description/meshes/forearm.dae"/>
      </geometry>
    </collision>
    <visual>
      <geometry>
        <mesh filename="package://kinova_description/meshes/ring_big.dae"/>
      </geometry>
    </visual>
    <collision>
      <geometry>
        <mesh filename="package://kinova_description/meshes/ring_big.dae"/>
      </geometry>
    </collision>
    <inertial>
      <mass value="0.6763"/>
      <origin xyz="0 0.081 -0.0086"/>
      <inertia ixx="0.00142022431908" ixy="0" ixz="0" iyy="0.000304335" iyz="0" izz="0.00142022431908"/>
    </inertial>
  </link>
  <joint name="j2n6s300_joint_3" type="revolute">
    <parent link="j2n6s300_link_2"/>
    <child link="j2n6s300_link_3"/>
    <axis xyz="0 0 1"/>
    <limit effort="40" lower="0.331612557879" upper="5.9515727493" velocity="0.628318530718"/>
    <origin rpy="0 3.14159265359 0" xyz="0 -0.410 0"/>
    <dynamics damping="0.0" friction="0.0"/>
  </joint>
  <transmission name="j2n6s300_joint_3_trans">
    <type>transmission_interface/SimpleTransmission</type>
    <joint name="j2n6s300_joint_3">
      <hardwareInterface>hardware_interface/EffortJointInterface</hardwareInterface>
    </joint>
    <actuator name="j2n6s300_joint_3_actuator">
      <hardwareInterface>hardware_interface/EffortJointInterface</hardwareInterface>
      <mechanicalReduction>160</mechanicalReduction>
    </actuator>
  </transmission>
  <!--For torque sensing in simulation-->
  <gazebo reference="j2n6s300_joint_3">
    <provideFeedback>true</provideFeedback>
  </gazebo>
  <gazebo>
    <plugin filename="libgazebo_ros_ft_sensor.so" name="ft_sensor">
      <updateRate>30.0</updateRate>
      <topicName>j2n6s300_joint_3_ft_sensor_topic</topicName>
      <jointName>j2n6s300_joint_3</jointName>
    </plugin>
  </gazebo>
  <link name="j2n6s300_link_4">
    <visual>
      <geometry>
        <mesh filename="package://kinova_description/meshes/wrist.dae"/>
      </geometry>
      <material name="carbon_fiber">
        <color rgba="0.792156862745098 0.819607843137255 0.933333333333333 1"/>
      </material>
    </visual>
    <collision>
      <geometry>
        <mesh filename="package://kinova_description/meshes/wrist.dae"/>
      </geometry>
    </collision>
    <visual>
      <geometry>
        <mesh filename="package://kinova_description/meshes/ring_small.dae"/>
      </geometry>
    </visual>
    <collision>
      <geometry>
        <mesh filename="package://kinova_description/meshes/ring_small.dae"/>
      </geometry>
    </collision>
    <inertial>
      <mass value="0.426367"/>
      <origin xyz="0 -0.037 -0.0642"/>
      <inertia ixx="7.73496906e-05" ixy="0" ixz="0" iyy="7.73496906e-05" iyz="0" izz="0.0001428"/>
    </inertial>
  </link>
  <joint name="j2n6s300_joint_4" type="continuous">
    <parent link="j2n6s300_link_3"/>
    <child link="j2n6s300_link_4"/>
    <axis xyz="0 0 1"/>
    <limit effort="20" lower="-6.28318530718" upper="6.28318530718" velocity="0.837758040957"/>
    <origin rpy="-1.57079632679 0 3.14159265359" xyz="0 0.2073 -0.0114"/>
    <dynamics damping="0.0" friction="0.0"/>
  </joint>
  <transmission name="j2n6s300_joint_4_trans">
    <type>transmission_interface/SimpleTransmission</type>
    <joint name="j2n6s300_joint_4">
      <hardwareInterface>hardware_interface/EffortJointInterface</hardwareInterface>
    </joint>
    <actuator name="j2n6s300_joint_4_actuator">
      <hardwareInterface>hardware_interface/EffortJointInterface</hardwareInterface>
      <mechanicalReduction>160</mechanicalReduction>
    </actuator>
  </transmission>
  <!--For torque sensing in simulation-->
  <gazebo reference="j2n6s300_joint_4">
    <provideFeedback>true</provideFeedback>
  </gazebo>
  <gazebo>
    <plugin filename="libgazebo_ros_ft_sensor.so" name="ft_sensor">
      <updateRate>30.0</updateRate>
      <topicName>j2n6s300_joint_4_ft_sensor_topic</topicName>
      <jointName>j2n6s300_joint_4</jointName>
    </plugin>
  </gazebo>
  <link name="j2n6s300_link_5">
    <visual>
      <geometry>
        <mesh filename="package://kinova_description/meshes/wrist.dae"/>
      </geometry>
      <material name="carbon_fiber">
        <color rgba="0.792156862745098 0.819607843137255 0.933333333333333 1"/>
      </material>
    </visual>
    <collision>
      <geometry>
        <mesh filename="package://kinova_description/meshes/wrist.dae"/>
      </geometry>
    </collision>
    <visual>
      <geometry>
        <mesh filename="package://kinova_description/meshes/ring_small.dae"/>
      </geometry>
    </visual>
    <collision>
      <geometry>
        <mesh filename="package://kinova_description/meshes/ring_small.dae"/>
      </geometry>
    </collision>
    <inertial>
      <mass value="0.426367"/>
      <origin xyz="0 -0.037 -0.0642"/>
      <inertia ixx="7.73496906e-05" ixy="0" ixz="0" iyy="7.73496906e-05" iyz="0" izz="0.0001428"/>
    </inertial>
  </link>
  <joint name="j2n6s300_joint_5" type="continuous">
    <parent link="j2n6s300_link_4"/>
    <child link="j2n6s300_link_5"/>
    <axis xyz="0 0 1"/>
    <limit effort="20" lower="-6.28318530718" upper="6.28318530718" velocity="0.837758040957"/>
    <origin rpy="1.0471975512 0 3.14159265359" xyz="0 -0.03703 -0.06414"/>
    <dynamics damping="0.0" friction="0.0"/>
  </joint>
  <transmission name="j2n6s300_joint_5_trans">
    <type>transmission_interface/SimpleTransmission</type>
    <joint name="j2n6s300_joint_5">
      <hardwareInterface>hardware_interface/EffortJointInterface</hardwareInterface>
    </joint>
    <actuator name="j2n6s300_joint_5_actuator">
      <hardwareInterface>hardware_interface/EffortJointInterface</hardwareInterface>
      <mechanicalReduction>160</mechanicalReduction>
    </actuator>
  </transmission>
  <!--For torque sensing in simulation-->
  <gazebo reference="j2n6s300_joint_5">
    <provideFeedback>true</provideFeedback>
  </gazebo>
  <gazebo>
    <plugin filename="libgazebo_ros_ft_sensor.so" name="ft_sensor">
      <updateRate>30.0</updateRate>
      <topicName>j2n6s300_joint_5_ft_sensor_topic</topicName>
      <jointName>j2n6s300_joint_5</jointName>
    </plugin>
  </gazebo>
  <link name="j2n6s300_link_6">
    <visual>
      <geometry>
        <mesh filename="package://kinova_description/meshes/hand_3finger.dae"/>
      </geometry>
      <material name="carbon_fiber">
        <color rgba="0.792156862745098 0.819607843137255 0.933333333333333 1"/>
      </material>
    </visual>
    <collision>
      <geometry>
        <mesh filename="package://kinova_description/meshes/hand_3finger.dae"/>
      </geometry>
    </collision>
    <visual>
      <geometry>
        <mesh filename="package://kinova_description/meshes/ring_small.dae"/>
      </geometry>
    </visual>
    <collision>
      <geometry>
        <mesh filename="package://kinova_description/meshes/ring_small.dae"/>
      </geometry>
    </collision>
    <inertial>
      <mass value="0.99"/>
      <origin xyz="0 0 -0.06"/>
      <inertia ixx="0.0003453236187" ixy="0" ixz="0" iyy="0.0003453236187" iyz="0" izz="0.0005816"/>
    </inertial>
  </link>
  <joint name="j2n6s300_joint_6" type="continuous">
    <parent link="j2n6s300_link_5"/>
    <child link="j2n6s300_link_6"/>
    <axis xyz="0 0 1"/>
    <limit effort="20" lower="-6.28318530718" upper="6.28318530718" velocity="0.837758040957"/>
    <origin rpy="1.0471975512 0 3.14159265359" xyz="0 -0.03703 -0.06414"/>
    <dynamics damping="0.0" friction="0.0"/>
  </joint>
  <transmission name="j2n6s300_joint_6_trans">
    <type>transmission_interface/SimpleTransmission</type>
    <joint name="j2n6s300_joint_6">
      <hardwareInterface>hardware_interface/EffortJointInterface</hardwareInterface>
    </joint>
    <actuator name="j2n6s300_joint_6_actuator">
      <hardwareInterface>hardware_interface/EffortJointInterface</hardwareInterface>
      <mechanicalReduction>160</mechanicalReduction>
    </actuator>
  </transmission>
  <!--For torque sensing in simulation-->
  <gazebo reference="j2n6s300_joint_6">
    <provideFeedback>true</provideFeedback>
  </gazebo>
  <gazebo>
    <plugin filename="libgazebo_ros_ft_sensor.so" name="ft_sensor">
      <updateRate>30.0</updateRate>
      <topicName>j2n6s300_joint_6_ft_sensor_topic</topicName>
      <jointName>j2n6s300_joint_6</jointName>
    </plugin>
  </gazebo>
  <link name="j2n6s300_end_effector"/>
  <joint name="j2n6s300_joint_end_effector" type="fixed">
    <parent link="j2n6s300_link_6"/>
    <child link="j2n6s300_end_effector"/>
    <axis xyz="0 0 0"/>
    <limit effort="2000" lower="0" upper="0" velocity="1"/>
    <origin rpy="3.14159265359 0 1.57079632679" xyz="0 0 -0.1600"/>
  </joint>
  <link name="j2n6s300_link_finger_1">
    <visual>
      <geometry>
        <mesh filename="package://kinova_description/meshes/finger_proximal.dae"/>
      </geometry>
      <material name="carbon_fiber">
        <color rgba="0.792156862745098 0.819607843137255 0.933333333333333 1"/>
      </material>
    </visual>
    <collision>
      <geometry>
        <mesh filename="package://kinova_description/meshes/finger_proximal.dae"/>
      </geometry>
    </collision>
    <inertial>
      <mass value="0.01"/>
      <origin xyz="0.022 0 0"/>
      <inertia ixx="7.8999684e-07" ixy="0" ixz="0" iyy="7.8999684e-07" iyz="0" izz="8e-08"/>
    </inertial>
  </link>
  <joint name="j2n6s300_joint_finger_1" type="revolute">
    <parent link="j2n6s300_link_6"/>
    <child link="j2n6s300_link_finger_1"/>
    <axis xyz="0 0 1"/>
    <origin rpy="-1.7047873384941834 0.6476144647144773 1.67317415161155" xyz="0.00279 0.03126 -0.11467"/>
    <limit effort="2" lower="0" upper="1.51" velocity="1"/>
  </joint>
  <transmission name="j2n6s300_joint_finger_1_trans">
    <type>transmission_interface/SimpleTransmission</type>
    <joint name="j2n6s300_joint_finger_1">
      <hardwareInterface>hardware_interface/EffortJointInterface</hardwareInterface>
    </joint>
    <actuator name="j2n6s300_joint_finger_1_actuator">
      <hardwareInterface>hardware_interface/EffortJointInterface</hardwareInterface>
      <mechanicalReduction>1</mechanicalReduction>
    </actuator>
  </transmission>
  <link name="j2n6s300_link_finger_tip_1">
    <visual>
      <geometry>
        <mesh filename="package://kinova_description/meshes/finger_distal.dae"/>
      </geometry>
      <material name="carbon_fiber">
        <color rgba="0.792156862745098 0.819607843137255 0.933333333333333 1"/>
      </material>
    </visual>
    <collision>
      <geometry>
        <mesh filename="package://kinova_description/meshes/finger_distal.dae"/>
      </geometry>
    </collision>
    <inertial>
      <mass value="0.01"/>
      <origin xyz="0.022 0 0"/>
      <inertia ixx="7.8999684e-07" ixy="0" ixz="0" iyy="7.8999684e-07" iyz="0" izz="8e-08"/>
    </inertial>
  </link>
  <joint name="j2n6s300_joint_finger_tip_1" type="revolute">
    <parent link="j2n6s300_link_finger_1"/>
    <child link="j2n6s300_link_finger_tip_1"/>
    <axis xyz="0 0 1"/>
    <origin rpy="0 0 0" xyz="0.044 -0.003 0"/>
    <limit effort="2" lower="0" upper="2" velocity="1"/>
  </joint>
  <transmission name="j2n6s300_joint_finger_tip_1_trans">
    <type>transmission_interface/SimpleTransmission</type>
    <joint name="j2n6s300_joint_finger_tip_1">
      <hardwareInterface>hardware_interface/EffortJointInterface</hardwareInterface>
    </joint>
    <actuator name="j2n6s300_joint_finger_tip_1_actuator">
      <hardwareInterface>hardware_interface/EffortJointInterface</hardwareInterface>
      <mechanicalReduction>1</mechanicalReduction>
    </actuator>
  </transmission>
  <link name="j2n6s300_link_finger_2">
    <visual>
      <geometry>
        <mesh filename="package://kinova_description/meshes/finger_proximal.dae"/>
      </geometry>
      <material name="carbon_fiber">
        <color rgba="0.792156862745098 0.819607843137255 0.933333333333333 1"/>
      </material>
    </visual>
    <collision>
      <geometry>
        <mesh filename="package://kinova_description/meshes/finger_proximal.dae"/>
      </geometry>
    </collision>
    <inertial>
      <mass value="0.01"/>
      <origin xyz="0.022 0 0"/>
      <inertia ixx="7.8999684e-07" ixy="0" ixz="0" iyy="7.8999684e-07" iyz="0" izz="8e-08"/>
    </inertial>
  </link>
  <joint name="j2n6s300_joint_finger_2" type="revolute">
    <parent link="j2n6s300_link_6"/>
    <child link="j2n6s300_link_finger_2"/>
    <axis xyz="0 0 1"/>
    <origin rpy="-1.570796327 .649262481663582 -1.38614049188413" xyz="0.02226 -0.02707 -0.11482"/>
    <limit effort="2" lower="0" upper="1.51" velocity="1"/>
  </joint>
  <transmission name="j2n6s300_joint_finger_2_trans">
    <type>transmission_interface/SimpleTransmission</type>
    <joint name="j2n6s300_joint_finger_2">
      <hardwareInterface>hardware_interface/EffortJointInterface</hardwareInterface>
    </joint>
    <actuator name="j2n6s300_joint_finger_2_actuator">
      <hardwareInterface>hardware_interface/EffortJointInterface</hardwareInterface>
      <mechanicalReduction>1</mechanicalReduction>
    </actuator>
  </transmission>
  <link name="j2n6s300_link_finger_tip_2">
    <visual>
      <geometry>
        <mesh filename="package://kinova_description/meshes/finger_distal.dae"/>
      </geometry>
      <material name="carbon_fiber">
        <color rgba="0.792156862745098 0.819607843137255 0.933333333333333 1"/>
      </material>
    </visual>
    <collision>
      <geometry>
        <mesh filename="package://kinova_description/meshes/finger_distal.dae"/>
      </geometry>
    </collision>
    <inertial>
      <mass value="0.01"/>
      <origin xyz="0.022 0 0"/>
      <inertia ixx="7.8999684e-07" ixy="0" ixz="0" iyy="7.8999684e-07" iyz="0" izz="8e-08"/>
    </inertial>
  </link>
  <joint name="j2n6s300_joint_finger_tip_2" type="revolute">
    <parent link="j2n6s300_link_finger_2"/>
    <child link="j2n6s300_link_finger_tip_2"/>
    <axis xyz="0 0 1"/>
    <origin rpy="0 0 0" xyz="0.044 -0.003 0"/>
    <limit effort="2" lower="0" upper="2" velocity="1"/>
  </joint>
  <transmission name="j2n6s300_joint_finger_tip_2_trans">
    <type>transmission_interface/SimpleTransmission</type>
    <joint name="j2n6s300_joint_finger_tip_2">
      <hardwareInterface>hardware_interface/EffortJointInterface</hardwareInterface>
    </joint>
    <actuator name="j2n6s300_joint_finger_tip_2_actuator">
      <hardwareInterface>hardware_interface/EffortJointInterface</hardwareInterface>
      <mechanicalReduction>1</mechanicalReduction>
    </actuator>
  </transmission>
  <link name="j2n6s300_link_finger_3">
    <visual>
      <geometry>
        <mesh filename="package://kinova_description/meshes/finger_proximal.dae"/>
      </geometry>
      <material name="carbon_fiber">
        <color rgba="0.792156862745098 0.819607843137255 0.933333333333333 1"/>
      </material>
    </visual>
    <collision>
      <geometry>
        <mesh filename="package://kinova_description/meshes/finger_proximal.dae"/>
      </geometry>
    </collision>
    <inertial>
      <mass value="0.01"/>
      <origin xyz="0.022 0 0"/>
      <inertia ixx="7.8999684e-07" ixy="0" ixz="0" iyy="7.8999684e-07" iyz="0" izz="8e-08"/>
    </inertial>
  </link>
  <joint name="j2n6s300_joint_finger_3" type="revolute">
    <parent link="j2n6s300_link_6"/>
    <child link="j2n6s300_link_finger_3"/>
    <axis xyz="0 0 1"/>
    <origin rpy="-1.570796327 .649262481663582 -1.75545216211587" xyz="-0.02226 -0.02707 -0.11482"/>
    <limit effort="2" lower="0" upper="1.51" velocity="1"/>
  </joint>
  <transmission name="j2n6s300_joint_finger_3_trans">
    <type>transmission_interface/SimpleTransmission</type>
    <joint name="j2n6s300_joint_finger_3">
      <hardwareInterface>hardware_interface/EffortJointInterface</hardwareInterface>
    </joint>
    <actuator name="j2n6s300_joint_finger_3_actuator">
      <hardwareInterface>hardware_interface/EffortJointInterface</hardwareInterface>
      <mechanicalReduction>1</mechanicalReduction>
    </actuator>
  </transmission>
  <link name="j2n6s300_link_finger_tip_3">
    <visual>
      <geometry>
        <mesh filename="package://kinova_description/meshes/finger_distal.dae"/>
      </geometry>
      <material name="carbon_fiber">
        <color rgba="0.792156862745098 0.819607843137255 0.933333333333333 1"/>
      </material>
    </visual>
    <collision>
      <geometry>
        <mesh filename="package://kinova_description/meshes/finger_distal.dae"/>
      </geometry>
    </collision>
    <inertial>
      <mass value="0.01"/>
      <origin xyz="0.022 0 0"/>
      <inertia ixx="7.8999684e-07" ixy="0" ixz="0" iyy="7.8999684e-07" iyz="0" izz="8e-08"/>
    </inertial>
  </link>
  <joint name="j2n6s300_joint_finger_tip_3" type="revolute">
    <parent link="j2n6s300_link_finger_3"/>
    <child link="j2n6s300_link_finger_tip_3"/>
    <axis xyz="0 0 1"/>
    <origin rpy="0 0 0" xyz="0.044 -0.003 0"/>
    <limit effort="2" lower="0" upper="2" velocity="1"/>
  </joint>
  <transmission name="j2n6s300_joint_finger_tip_3_trans">
    <type>transmission_interface/SimpleTransmission</type>
    <joint name="j2n6s300_joint_finger_tip_3">
      <hardwareInterface>hardware_interface/EffortJointInterface</hardwareInterface>
    </joint>
    <actuator name="j2n6s300_joint_finger_tip_3_actuator">
      <hardwareInterface>hardware_interface/EffortJointInterface</hardwareInterface>
      <mechanicalReduction>1</mechanicalReduction>
    </actuator>
  </transmission>
</robot>
